<mujoco model="exercise_1">
    <visual>
        <headlight ambient="0.6 0.6 0.6" />
    </visual>

    <option gravity="0 0 -9.81" />

    <worldbody>
        <!-- Plane -->
        <geom type="plane" pos="-0.4 -0.4 0" size="1.2 1.2 0.1" rgba="0 0 1 1"/>

        <!-- Main body -->
        <body name="main_body" euler="0 0 0">
            <!-- Top box -->
            <geom name="top_box" type="box" pos="0 0 0.3" size="0.08 0.06 0.08" rgba="0.5 0.3 0.2 0.7"/>

            <!-- Bottom box -->
            <geom name="bottom_box" type="box" pos="0 0 0.12" size="0.12 0.06 0.12" rgba="0.5 0.3 0.2 1"/>

            <!-- Center sphere -->
            <geom name="center_sphere" type="sphere" pos="0 0 0.22" size="0.04" rgba="0.5 0.2 0.5 1"/>
        </body>

        <!-- Motor A -->
        <body name="motor_A" euler="0 0 0">
            <!-- Cylinder for motor A -->
            <geom name="cylinder_A" type="cylinder" fromto="0.12 -0.09 0.23 0.08 -0.09 0.23" size="0.0198" rgba="0.2 0.2 0.7 0.8" mass="65"/>

            <!-- Hinge joint A -->
            <joint name="hinge_A" type="hinge" pos="0.1 -0.09 0.23" axis="1 0 0"/>

            <!-- Motor B -->
            <body name="motor_B" euler="0 0 0">
                <!-- Cylinder for motor B -->
                <geom name="cylinder_B" type="cylinder" fromto="0.15 -0.09 0.25 0.15 -0.09 0.18" size="0.0198" rgba="0.2 0.7 0.2 0.8" mass="65"/>

                <!-- Hinge joint B -->
                <joint name="hinge_B" type="hinge" pos="0.15 -0.09 0.23" axis="0 0 1"/>

                <!-- Motor C -->
                <body name="motor_C" euler="0 0 0">
                    <!-- Cylinder for motor C -->
                    <geom name="cylinder_C" type="cylinder" fromto="0.15 -0.05 0.23 0.15 0.03 0.23" size="0.0198" rgba="0.7 0.2 0.2 0.8" mass="65"/>

                    <!-- Hinge joint C -->
                    <joint name="hinge_C" type="hinge" pos="0.15 0 0.23" axis="0 1 0"/>

                    <!-- Link A -->
                    <geom name="link_A" type="box" pos="0.15 0.07 0.23" size="0.012 0.1 0.012" rgba="0.3 0.6 0.3 1" mass="0.02"/>

                    <!-- Elbow A -->
                    <body name="elbow_A" euler="0 0 0">
                        <!-- Cylinder for elbow A -->
                        <geom name="cylinder_elbow_A" type="cylinder" fromto="0.17 0.17 0.23 0.14 0.17 0.23" size="0.04" rgba="0.2 0.2 0.2 0.8"/>

                        <!-- Mass link B -->
                        <body name="mass_link_B" euler="0 0 0">
                            <!-- Hinge joint D -->
                            <joint name="hinge_D" type="hinge" pos="0.15 0.17 0.23" axis="1 0 0"/>

                            <!-- Mass B -->
                            <geom name="mass_B" type="sphere" pos="0.15 0.37 0.23" size="0.06" rgba="0.7 0.3 0.4 1" mass="0.02"/>

                            <!-- Link B -->
                            <geom name="link_B" type="box" pos="0.15 0.27 0.23" size="0.012 0.1 0.012" rgba="0.6 0.3 0.7 1" mass="0.02"/>
                        </body>
                    </body>
                </body>
            </body>
        </body>
    </worldbody>
</mujoco>

