<mujoco model="task1_modified">
    <visual>
        <headlight ambient="0.5 0.5 0.5" />
    </visual>

    <option gravity="0 0 -9.81" />

    <worldbody>
        <light name="overhead" pos="0 0 1"/>
        <geom type="plane" pos="-0.5 -0.5 0" size="1 1 0.1" rgba="0 .9 0 1"/>
        <body name="base_section" euler="0 0 0">
            <geom name="lower_part" type="box" pos="0 0 0.1" size=".1 .05 .1" rgba="0.2 0.2 0.2 1"/>
            <geom name="ball_joint" pos="0 0 .2" size=".01" rgba="0.2 0.2 0.2 1"/>
            <geom name="upper_section" type="box" pos="0 0 .27" size=".07 .05 .07" rgba="0.2 0.2 0.2 0.7"/>
        </body>
        <body name="actuator1" euler="0 0 0">
            <geom type="cylinder" fromto="0.12 -.08 0.2 0.095 -.08 0.2" size=".018" mass="0.065" rgba=".1 .1 .1 .8"/>
            <joint name="pivot_1" pos="0.105 -.08 0.2" axis="1 0 0"/>
            <body name="actuator2" euler="0 0 0">
                <geom type="cylinder" fromto="0.145 -.08 0.19 0.145 -.08 0.21" size=".018" mass="0.065" rgba=".1 .1 .1 .8"/>
                <joint name="pivot_2" pos="0.145 -.08 0.2" axis="0 0 1"/>
                <body name="actuator3" euler="0 0 0">
                    <geom type="cylinder" fromto="0.145 -.055 0.2 0.145 -.035 0.2" size=".018" mass="0.065" rgba=".1 .1 .1 .8"/>
                    <joint name="pivot_3" pos="0.145 -.045 0.2" axis="0 1 0"/>
                    <body name="link_1" euler="0 0 0">
                        <geom name="connector1" type="box" pos="0.145 .02 0.2" size=".005 .05 .005" mass="0.02" rgba="0.2 0.5 0.2 1"/>
                        <body name="joint1" euler="0 0 0">
                            <geom type="cylinder" fromto="0.1335 0.09 0.2 0.1565 0.09 0.2" size=".018" mass="0.065" rgba=".1 .1 .1 .8"/>
                            <joint name="pivot_4" pos="0.145 0.09 0.2" axis="1 0 0"/>
                            <body name="link_2" euler="0 0 0">
                                <geom name="connector2" type="box" pos="0.145 0.16 0.2" size=".005 .05 .005" mass="0.02" rgba="0.2 0.2 0.5 1"/>
                                <body name="end_mass" euler="0 0 0">
                                    <geom name="mass_block" pos="0.145 0.23 0.2" size=".02" mass="0.02" rgba="0.5 0.2 0.2 1"/>
                                </body>
                            </body>
                        </body>
                    </body>
                </body>
            </body>
        </body>
    </worldbody>
</mujoco>

